Workbook
Name avg_equity: Ratios!$C$33
Name avg_total_assets: Ratios!$C$34
Name avg_total_capitalization: Ratios!$C$35
Name cost_capital: Ratios!$C$7
Name currentYear_after_tax_operating_income: Ratios!$C$19
Name currentYear_assets_current: Ratios!$C$23
Name currentYear_assets_total: Ratios!$C$28
Name currentYear_cash_marketable_securities: Ratios!$C$22
Name currentYear_cost_goods_sold_daily: Ratios!$C$25
Name currentYear_daily_sales_average: Ratios!$C$20
Name currentYear_debt_long_term: Ratios!$C$26
Name currentYear_equity: Ratios!$C$21
Name currentYear_liabilities_current: Ratios!$C$24
Name currentYear_liabilities_total: Ratios!$C$30
Name currentYear_total_capitalization: Ratios!$C$29
Name currentYear_working_capital_net: Ratios!$C$27
Name debt_long_term_equity: Ratios!$C$36
Name INC_cost_goods_sold: 'Income Statement'!$C$5
Name INC_depreciation: 'Income Statement'!$C$7
Name INC_ebit: 'Income Statement'!$C$8
Name INC_interest_expense: 'Income Statement'!$C$11
Name INC_net: 'Income Statement'!$C$15
Name INC_sales: 'Income Statement'!$C$4
Name market_capitalization: Ratios!$C$9
Name RATIO_asset_turnover: Ratios!$C$54
Name RATIO_debt_burden: Ratios!$C$68
Name RATIO_leverage: Ratios!$C$69
Name RATIO_operating_profit_margin: Ratios!$C$60
Name share_price: Ratios!$C$5
Name shares_outstanding: Ratios!$C$6
Name startYear_equity: Ratios!$C$12
Name startYear_inventory: Ratios!$C$13
Name startYear_receivables: Ratios!$C$14
Name startYear_total_assets: Ratios!$C$15
Name startYear_total_capitalization: Ratios!$C$16
Name tax_rate: Ratios!$C$8
Name yearCurrent: Ratios!$C$3
Name yearStart: Ratios!$C$4

Sheet Balance Sheet
B1: Balance Sheet — Caterpillar Inc. (CAT)
B2: ASSETS | C2: FY2024 (Dec 31, 2024) | D2: FY2023 (Dec 31, 2023) | F2: LIABILITIES & EQUITY | G2: FY2024 (Dec 31, 2024) | H2: FY2023 (Dec 31, 2023)
B3: (All figures in $millions) | F3: (All figures in $millions)
B4: Current Assets | F4: Current Liabilities
B5: Cash and cash equivalents | C5: 6889 | D5: 6978 | F5: Short-term borrowings | G5: 4393 | H5: 4643
B6: Receivables — trade and other | C6: 9282 | D6: 9310 | F6: Accounts payable | G6: 7675 | H6: 7906
B7: Receivables — finance (Cat Financial) | C7: 9565 | D7: 9510 | F7: Accrued expenses | G7: 5243 | H7: 4958
B8: Inventories | C8: 16827 | D8: 16565 | F8: Accrued wages, salaries & benefits | G8: 2391 | H8: 2757
B9: Other current assets | C9: 3119 | D9: 4586 | F9: Customer advances | G9: 2322 | H9: 1929
B10: Total current assets | C10: =SUM(C5:C9) -> 45682 | D10: =SUM(D5:D9) -> 46949 | F10: Dividends payable | G10: 674 | H10: 649
F11: Other current liabilities | G11: 2909 | H11: 3123
B12: Property, plant, and equipment | C12: 22574 | D12: 21497 | F12: Long-term debt due within one year | G12: 6665 | H12: 8763
B13: Less accumulated depreciation | C13: 9213 | D13: 8817 | F13: Total current liabilities | G13: =SUM(G5:G12) -> 32272 | H13: =SUM(H5:H12) -> 34728
B14: Net tangible fixed assets | C14: =C12-C13 -> 13361 | D14: =D12-D13 -> 12680
F15: Long-term debt due after one year | G15: 27351 | H15: 24472
B16: Long-term receivables — trade and finance | C16: 14467 | D16: 13902 | F16: Liability for postemployment benefits | G16: 3757 | H16: 4098
B17: Deferred income taxes (noncurrent) | C17: 3312 | D17: 2816 | F17: Other liabilities | G17: 4890 | H17: 4675
F18: Total Liabilities | G18: =G13+G15+G16+G17 -> 68270 | H18: =H13+H15+H16+H17 -> 67973
B19: Other Assets
B20: Intangible assets (goodwill) | C20: 5640 | D20: 5872 | F20: Shareholders' Equity
B21: Other assets | C21: 5302 | D21: 5257 | F21: Common stock | G21: 6941 | H21: 6403
B22: Other assets | C22: =SUM(C20:C21) -> 10942 | D22: =SUM(D20:D21) -> 11129 | F22: Treasury stock | G22: -44331 | H22: -36339
F23: Profit employed in the business | G23: 59352 | H23: 51250
F24: Accumulated other comprehensive income (loss) | G24: -2471 | H24: -1820
F25: Noncontrolling interests | G25: 3 | H25: 9
F26: Total shareholders' equity | G26: =SUM(G21:G25) -> 19494 | H26: =SUM(H21:H25) -> 19503
B27: Total Assets | C27: =C10+C14+C16+C17+C22 -> 87764 | D27: =D10+D14+D16+D17+D22 -> 87476
B28: Balance Check (TA − TL&E) | C28: =C27-G28 -> 0 | F28: Total Liabilities + Equity | G28: =G18+G26 -> 87764 | H28: =H18+H26 -> 87476
B29: Source: Caterpillar 10-K FY2024, SEC EDGAR

Sheet Income Statement
B1: Income Statement — Caterpillar Inc. (CAT)
B2: Line Item | C2: FY2024 (Dec 31, 2024) | D2: % of Sales
B3: (All figures in $millions)
B4: Net sales | C4: 64809 | D4: =IF(C$4=0,0,C4/C$4) -> 1
B5: less Cost of goods sold | C5: 43244 | D5: =IF(C$4=0,0,C5/C$4) -> 0.667253
B6: less Selling, general & administrative | C6: 5965 | D6: =IF(C$4=0,0,C6/C$4) -> 0.092039686
B7: less Depreciation | C7: 1413 | D7: =IF(C$4=0,0,C7/C$4) -> 0.021802527
B8: Earnings before interest & taxes (EBIT) | C8: =C4-C5-C6-C7 -> 14187 | D8: =IF(C$4=0,0,C8/C$4) -> 0.21890478
D9: =IF(C$4=0,0,C9/C$4) -> 0
B10: plus Other income | C10: 2116 | D10: =IF(C$4=0,0,C10/C$4) -> 0.032649786
B11: less Interest expense | C11: 1713 | D11: =IF(C$4=0,0,C11/C$4) -> 0.026431514
B12: Taxable income | C12: =C8+C10-C11 -> 14590 | D12: =IF(C$4=0,0,C12/C$4) -> 0.22512305
D13: =IF(C$4=0,0,C13/C$4) -> 0
B14: less Taxes | C14: 2944 | D14: =IF(C$4=0,0,C14/C$4) -> 0.04542579
B15: Net income | C15: =C12-C14 -> 11646 | D15: =IF(C$4=0,0,C15/C$4) -> 0.17969726
D16: =IF(C$4=0,0,C16/C$4) -> 0
B17: Allocation of Net Income | C17: =C15-C16 -> 11646 | D17: =IF(C$4=0,0,C17/C$4) -> 0.17969726
B18: Dividends | C18: 2736 | D18: =IF(C$4=0,0,C18/C$4) -> 0.042216359
B19: Addition to retained earnings | C19: =C17-C18 -> 8910 | D19: =IF(C$4=0,0,C19/C$4) -> 0.13748091
B21: Source: Caterpillar 10-K FY2024, SEC EDGAR

Sheet Cash Flow Statement
B1: Cash Flow Statement — Caterpillar Inc. (CAT)
B2: Line Item | C2: FY2024 (Dec 31, 2024) | D2: Source / Notes
B3: (All figures in $millions)
B4: Operations:
B5: Net income | C5: 11646 | D5: [Income Statement]
B6: plus Depreciation | C6: 1413 | D6: [Income Statement]
B7: plus Changes in working capital items
B8: Decrease (increase) in accounts receivable | C8: =-('Balance Sheet'!C6-'Balance Sheet'!D6) -> 28 | D8: [Balance Sheet]
B9: Decrease (increase) in inventories | C9: =-('Balance Sheet'!C8-'Balance Sheet'!D8) -> -262 | D9: [Balance Sheet]
B10: Decrease (increase) in other current assets | C10: =-('Balance Sheet'!C9-'Balance Sheet'!D9) -> 1467 | D10: [Balance Sheet]
B11: Increase (decrease) in accounts payable | C11: ='Balance Sheet'!G6-'Balance Sheet'!H6 -> -231 | D11: [Balance Sheet]
B12: Increase (decrease) in other current liabilities | C12: =SUM('Balance Sheet'!G7:G11)-SUM('Balance Sheet'!H7:H11) -> 123 | D12: [Balance Sheet]
B13: Total change in working capital | C13: =SUM(C8:C12) -> 1125
B14: Cash provided by operations | C14: =C5+C6+C13 -> 14184
B16: Investments:
B17: Capital expenditures | C17: -1702
B18: plus Sales (acquisitions) of long-term assets | C18: 298
B19: plus Other investing activities | C19: -782
B20: Cash provided by (used for) investments | C20: =SUM(C17:C19) -> -2186
B22: Financing activities:
B23: Increase (decrease) in short-term debt | C23: 689
B24: plus Increase (decrease) in long-term debt | C24: -61
B25: plus Dividends | C25: -2736
B26: plus Issues (repurchases) of stock | C26: -7839
B27: plus Other | C27: -327
B28: Cash provided by (used for) financing | C28: =SUM(C23:C27) -> -10274
B30: Net increase (decrease) in cash | C30: =C14+C20+C28 -> 1724
B32: Source: Caterpillar 10-K FY2024, SEC EDGAR

Sheet Ratios
B1: Ratios — Caterpillar Inc. (CAT)
B2: Metric | C2: Input | D2: Named Range Formula | E2: Named Range
B3: Current year | C3: 2024 | E3: yearCurrent
B4: Start of year | C4: 2023 | D4: yearCurrent - 1 | E4: yearStart
B5: Share price | C5: 349.58 | E5: share_price
B6: Shares outstanding (M) | C6: 492 | E6: shares_outstanding
B7: Cost of capital | C7: 0.079 | E7: cost_capital
B8: Tax rate | C8: 0.214 | E8: tax_rate
B9: Market capitalization | C9: =C5*C6 -> 171993.36 | D9: share_price × shares_outstanding | E9: market_capitalization
B11: ─── Start of Year (Prior Year Balance Sheet) ───
B12: Equity (start of year) | C12: ='Balance Sheet'!H26 -> 19503 | D12: BAL_equity_shareholders_2023 | E12: startYear_equity
B13: Inventories (start of year) | C13: ='Balance Sheet'!D8 -> 16565 | D13: BAL_inventories_2023 | E13: startYear_inventory
B14: Receivables (start of year) | C14: ='Balance Sheet'!D6 -> 9310 | D14: BAL_receivables_2023 | E14: startYear_receivables
B15: Total assets (start of year) | C15: ='Balance Sheet'!D27 -> 87476 | D15: BAL_assets_total_2023 | E15: startYear_total_assets
B16: Total capitalization (start of year) | C16: ='Balance Sheet'!H15+'Balance Sheet'!H26 -> 43975 | D16: BAL_debt_long_term_2023 + BAL_equity_shareholders_2023 | E16: startYear_total_capitalization
B18: ─── Current Year (Derived) ───
B19: After-tax operating income | C19: ='Income Statement'!C15+(1-C8)*'Income Statement'!C11 -> 12992.418 | D19: INC_net + (1−tax_rate) × INC_interest_expense | E19: currentYear_after_tax_operating_income
B20: Average daily sales | C20: ='Income Statement'!C4/365 -> 177.5589 | D20: INC_sales / 365 | E20: currentYear_daily_sales_average
B21: Book value of equity | C21: ='Balance Sheet'!G26 -> 19494 | D21: BAL_equity_shareholders_2024 | E21: currentYear_equity
B22: Cash + Mktable securities | C22: ='Balance Sheet'!C5 -> 6889 | D22: BAL_cash_marketable_securities_2024 | E22: currentYear_cash_marketable_securities
B23: Current assets | C23: ='Balance Sheet'!C10 -> 45682 | D23: BAL_assets_current_2024 | E23: currentYear_assets_current
B24: Current liabilities | C24: ='Balance Sheet'!G13 -> 32272 | D24: BAL_liabilities_current_2024 | E24: currentYear_liabilities_current
B25: Daily COGS | C25: ='Income Statement'!C5/365 -> 118.47671 | D25: INC_cost_goods_sold / 365 | E25: currentYear_cost_goods_sold_daily
B26: Long-term debt | C26: ='Balance Sheet'!G15 -> 27351 | D26: BAL_debt_long_term_2024 | E26: currentYear_debt_long_term
B27: Net working capital | C27: ='Balance Sheet'!C10-'Balance Sheet'!G13 -> 13410 | D27: BAL_assets_current_2024 − BAL_liabilities_current_2024 | E27: currentYear_working_capital_net
B28: Total assets | C28: ='Balance Sheet'!C27 -> 87764 | D28: BAL_assets_total_2024 | E28: currentYear_assets_total
B29: Total capitalization | C29: ='Balance Sheet'!G15+'Balance Sheet'!G26 -> 46845 | D29: BAL_debt_long_term_2024 + BAL_equity_shareholders_2024 | E29: currentYear_total_capitalization
B30: Total liabilities | C30: ='Balance Sheet'!G18 -> 68270 | D30: BAL_liabilities_total_2024 | E30: currentYear_liabilities_total
B32: ─── Mixed Year (Averages) ───
B33: Average equity | C33: =AVERAGE(C12,C21) -> 19498.5 | D33: AVERAGE(startYear_equity, currentYear_equity) | E33: avg_equity
B34: Average total assets | C34: =AVERAGE(C15,C28) -> 87620 | D34: AVERAGE(startYear_total_assets, currentYear_assets_total) | E34: avg_total_assets
B35: Average total capitalization | C35: =AVERAGE(C16,C29) -> 45410 | D35: AVERAGE(startYear_total_capitalization, currentYear_total_capitalization) | E35: avg_total_capitalization
B36: Long-term debt + Equity | C36: =C26+C21 -> 46845 | D36: currentYear_debt_long_term + currentYear_equity | E36: debt_long_term_equity
B39: Ratio | C39: Output ← Students Complete | D39: Named Range Formula (reference) | E39: Named Range
B40: Performance
B41: Market value added (MVA) | C41: =market_capitalization-currentYear_equity -> 152499.36 | D41: market_capitalization − currentYear_equity
B42: Market-to-book ratio | C42: =market_capitalization/currentYear_equity -> 8.822887 | D42: market_capitalization / currentYear_equity
B43: Economic value added (EVA) | C43: =currentYear_after_tax_operating_income-(cost_capital*startYear_total_capitalization) -> 9518.393 | D43: currentYear_after_tax_operating_income − (cost_capital × startYear_total_capitalization)
B45: Profitability
B46: Return on assets (ROA) | C46: =currentYear_after_tax_operating_income/startYear_total_assets -> 0.14852552 | D46: currentYear_after_tax_operating_income / startYear_total_assets
...

Sheet Notes
B1: Notes & Assumptions — Caterpillar Inc. (CAT)
B3: Company: | C3: Caterpillar Inc.
B4: Ticker: | C4: CAT
B5: Industry: | C5: Industrials – Heavy Machinery & Equipment
B6: Fiscal Year (current): | C6: FY2024 (Dec 31, 2024)
B7: Fiscal Year (prior): | C7: FY2023 (Dec 31, 2023)
B8: Data Source: | C8: Caterpillar 10-K FY2024, SEC EDGAR
B9: Units: | C9: All figures in millions of US dollars unless otherwise noted.
B10: Tax Rate: | C10: 21.4% — assumed
B11: Cost of Capital: | C11: 7.9% — estimated WACC
B12: Share Price: | C12: $349.58 — end-of-fiscal-year closing price
B13: Shares Outstanding: | C13: 492M shares
B15: Color Coding:
B16: Yellow = Editable input cells
B17: Blue = Assumptions
B18: Green = Formula cells
B19: Gray = Output / summary cells
B21: AI Usage: | C21: Claude - formula refinement, data pulling from 10K, and final formating.
C22: startYear_equity → now correctly pulls Total Shareholders' Equity FY2023 (was pulling Treasury Stock)
C23: startYear_total_capitalization → corrected to LT Debt + Equity FY2023
C24: after_tax_operating_income → fixed to Net Income + (1−tax) × Interest Expense (was referencing wrong income statement rows)
C25: currentYear_equity → Total Shareholders' Equity FY2024
C26: currentYear_liabilities_current → Total Current Liabilities (was pulling Customer Advances)
C27: currentYear_debt_long_term → LT Debt Due After One Year (was pulling Other Current Liabilities)
C28: currentYear_total_capitalization → corrected LT Debt + Equity FY2024
C29: currentYear_liabilities_total → Total Liabilities FY2024
C30: named ranges added (RATIO_asset_turnover, RATIO_operating_profit_margin, RATIO_debt_burden, RATIO_leverage) for Du Pont cross-references.
C31: ROE, ROE [avg], Profit Margin, Debt Burden → now use INC_net
C32: Asset Turnover, Receivables Turnover, Operating Profit Margin → now use INC_sales
C33: Inventory Turnover → now uses INC_cost_goods_sold
... C36: All Du Pont formulas → now use RATIO_* named ranges throughout
